2024-12-01 18:17:10,574 - app - ERROR - Exception on /check-inbox [GET]
Traceback (most recent call last):
  File "/home/antonio/Escritorio/Uni/EGC/uvlhub_hijo/venv/lib/python3.12/site-packages/flask/app.py", line 1473, in wsgi_app
    response = self.full_dispatch_request()
               ^^^^^^^^^^^^^^^^^^^^^^^^^^^^
  File "/home/antonio/Escritorio/Uni/EGC/uvlhub_hijo/venv/lib/python3.12/site-packages/flask/app.py", line 882, in full_dispatch_request
    rv = self.handle_user_exception(e)
         ^^^^^^^^^^^^^^^^^^^^^^^^^^^^^
  File "/home/antonio/Escritorio/Uni/EGC/uvlhub_hijo/venv/lib/python3.12/site-packages/flask_restful/__init__.py", line 298, in error_router
    return original_handler(e)
           ^^^^^^^^^^^^^^^^^^^
  File "/home/antonio/Escritorio/Uni/EGC/uvlhub_hijo/venv/lib/python3.12/site-packages/flask/app.py", line 880, in full_dispatch_request
    rv = self.dispatch_request()
         ^^^^^^^^^^^^^^^^^^^^^^^
  File "/home/antonio/Escritorio/Uni/EGC/uvlhub_hijo/venv/lib/python3.12/site-packages/flask/app.py", line 865, in dispatch_request
    return self.ensure_sync(self.view_functions[rule.endpoint])(**view_args)  # type: ignore[no-any-return]
           ^^^^^^^^^^^^^^^^^^^^^^^^^^^^^^^^^^^^^^^^^^^^^^^^^^^^^^^^^^^^^^^^^
  File "/home/antonio/Escritorio/Uni/EGC/uvlhub_hijo/app/modules/auth/routes.py", line 46, in check_inbox
    return render_template("auth/check_inbox.html")
           ^^^^^^^^^^^^^^^^^^^^^^^^^^^^^^^^^^^^^^^^
  File "/home/antonio/Escritorio/Uni/EGC/uvlhub_hijo/venv/lib/python3.12/site-packages/flask/templating.py", line 149, in render_template
    template = app.jinja_env.get_or_select_template(template_name_or_list)
               ^^^^^^^^^^^^^^^^^^^^^^^^^^^^^^^^^^^^^^^^^^^^^^^^^^^^^^^^^^^
  File "/home/antonio/Escritorio/Uni/EGC/uvlhub_hijo/venv/lib/python3.12/site-packages/jinja2/environment.py", line 1084, in get_or_select_template
    return self.get_template(template_name_or_list, parent, globals)
           ^^^^^^^^^^^^^^^^^^^^^^^^^^^^^^^^^^^^^^^^^^^^^^^^^^^^^^^^^
  File "/home/antonio/Escritorio/Uni/EGC/uvlhub_hijo/venv/lib/python3.12/site-packages/jinja2/environment.py", line 1013, in get_template
    return self._load_template(name, globals)
           ^^^^^^^^^^^^^^^^^^^^^^^^^^^^^^^^^^
  File "/home/antonio/Escritorio/Uni/EGC/uvlhub_hijo/venv/lib/python3.12/site-packages/jinja2/environment.py", line 972, in _load_template
    template = self.loader.load(self, name, self.make_globals(globals))
               ^^^^^^^^^^^^^^^^^^^^^^^^^^^^^^^^^^^^^^^^^^^^^^^^^^^^^^^^
  File "/home/antonio/Escritorio/Uni/EGC/uvlhub_hijo/venv/lib/python3.12/site-packages/jinja2/loaders.py", line 138, in load
    code = environment.compile(source, name, filename)
           ^^^^^^^^^^^^^^^^^^^^^^^^^^^^^^^^^^^^^^^^^^^
  File "/home/antonio/Escritorio/Uni/EGC/uvlhub_hijo/venv/lib/python3.12/site-packages/jinja2/environment.py", line 768, in compile
    self.handle_exception(source=source_hint)
  File "/home/antonio/Escritorio/Uni/EGC/uvlhub_hijo/venv/lib/python3.12/site-packages/jinja2/environment.py", line 939, in handle_exception
    raise rewrite_traceback_stack(source=source)
  File "/home/antonio/Escritorio/Uni/EGC/uvlhub_hijo/app/modules/auth/templates/auth/check_inbox.html", line 10, in template
    {% comment %} <p>If you don't receive the email within a few minutes, click the button below to resend the email.</p>
    ^^^^^^^^^^^^^^^^^^^^^^^^^
jinja2.exceptions.TemplateSyntaxError: Encountered unknown tag 'comment'. Jinja was looking for the following tags: 'endblock'. The innermost block that needs to be closed is 'block'.
2024-12-01 18:17:10,577 - app - ERROR - Internal Server Error: 500 Internal Server Error: The server encountered an internal error and was unable to complete your request. Either the server is overloaded or there is an error in the application.
2024-12-01 18:17:39,069 - app - ERROR - Exception on /check-inbox [GET]
Traceback (most recent call last):
  File "/home/antonio/Escritorio/Uni/EGC/uvlhub_hijo/venv/lib/python3.12/site-packages/flask/app.py", line 1473, in wsgi_app
    response = self.full_dispatch_request()
               ^^^^^^^^^^^^^^^^^^^^^^^^^^^^
  File "/home/antonio/Escritorio/Uni/EGC/uvlhub_hijo/venv/lib/python3.12/site-packages/flask/app.py", line 882, in full_dispatch_request
    rv = self.handle_user_exception(e)
         ^^^^^^^^^^^^^^^^^^^^^^^^^^^^^
  File "/home/antonio/Escritorio/Uni/EGC/uvlhub_hijo/venv/lib/python3.12/site-packages/flask_restful/__init__.py", line 298, in error_router
    return original_handler(e)
           ^^^^^^^^^^^^^^^^^^^
  File "/home/antonio/Escritorio/Uni/EGC/uvlhub_hijo/venv/lib/python3.12/site-packages/flask/app.py", line 880, in full_dispatch_request
    rv = self.dispatch_request()
         ^^^^^^^^^^^^^^^^^^^^^^^
  File "/home/antonio/Escritorio/Uni/EGC/uvlhub_hijo/venv/lib/python3.12/site-packages/flask/app.py", line 865, in dispatch_request
    return self.ensure_sync(self.view_functions[rule.endpoint])(**view_args)  # type: ignore[no-any-return]
           ^^^^^^^^^^^^^^^^^^^^^^^^^^^^^^^^^^^^^^^^^^^^^^^^^^^^^^^^^^^^^^^^^
  File "/home/antonio/Escritorio/Uni/EGC/uvlhub_hijo/app/modules/auth/routes.py", line 46, in check_inbox
    return render_template("auth/check_inbox.html")
           ^^^^^^^^^^^^^^^^^^^^^^^^^^^^^^^^^^^^^^^^
  File "/home/antonio/Escritorio/Uni/EGC/uvlhub_hijo/venv/lib/python3.12/site-packages/flask/templating.py", line 149, in render_template
    template = app.jinja_env.get_or_select_template(template_name_or_list)
               ^^^^^^^^^^^^^^^^^^^^^^^^^^^^^^^^^^^^^^^^^^^^^^^^^^^^^^^^^^^
  File "/home/antonio/Escritorio/Uni/EGC/uvlhub_hijo/venv/lib/python3.12/site-packages/jinja2/environment.py", line 1084, in get_or_select_template
    return self.get_template(template_name_or_list, parent, globals)
           ^^^^^^^^^^^^^^^^^^^^^^^^^^^^^^^^^^^^^^^^^^^^^^^^^^^^^^^^^
  File "/home/antonio/Escritorio/Uni/EGC/uvlhub_hijo/venv/lib/python3.12/site-packages/jinja2/environment.py", line 1013, in get_template
    return self._load_template(name, globals)
           ^^^^^^^^^^^^^^^^^^^^^^^^^^^^^^^^^^
  File "/home/antonio/Escritorio/Uni/EGC/uvlhub_hijo/venv/lib/python3.12/site-packages/jinja2/environment.py", line 972, in _load_template
    template = self.loader.load(self, name, self.make_globals(globals))
               ^^^^^^^^^^^^^^^^^^^^^^^^^^^^^^^^^^^^^^^^^^^^^^^^^^^^^^^^
  File "/home/antonio/Escritorio/Uni/EGC/uvlhub_hijo/venv/lib/python3.12/site-packages/jinja2/loaders.py", line 138, in load
    code = environment.compile(source, name, filename)
           ^^^^^^^^^^^^^^^^^^^^^^^^^^^^^^^^^^^^^^^^^^^
  File "/home/antonio/Escritorio/Uni/EGC/uvlhub_hijo/venv/lib/python3.12/site-packages/jinja2/environment.py", line 768, in compile
    self.handle_exception(source=source_hint)
  File "/home/antonio/Escritorio/Uni/EGC/uvlhub_hijo/venv/lib/python3.12/site-packages/jinja2/environment.py", line 939, in handle_exception
    raise rewrite_traceback_stack(source=source)
  File "/home/antonio/Escritorio/Uni/EGC/uvlhub_hijo/app/modules/auth/templates/auth/check_inbox.html", line 10, in template
    {% comment %} <p>If you don't receive the email within a few minutes, click the button below to resend the email.</p>
    ^^^^^^^^^^^^^^^^^^^^^^^^^
jinja2.exceptions.TemplateSyntaxError: Encountered unknown tag 'comment'. Jinja was looking for the following tags: 'endblock'. The innermost block that needs to be closed is 'block'.
2024-12-01 18:17:39,073 - app - ERROR - Internal Server Error: 500 Internal Server Error: The server encountered an internal error and was unable to complete your request. Either the server is overloaded or there is an error in the application.
