2024-12-14 19:31:42,623 - app - ERROR - Exception on / [GET]
Traceback (most recent call last):
  File "/home/antonio/Escritorio/Uni/EGC/uvlhub_hijo/venv/lib/python3.12/site-packages/sqlalchemy/engine/base.py", line 1967, in _exec_single_context
    self.dialect.do_execute(
  File "/home/antonio/Escritorio/Uni/EGC/uvlhub_hijo/venv/lib/python3.12/site-packages/sqlalchemy/engine/default.py", line 924, in do_execute
    cursor.execute(statement, parameters)
  File "/home/antonio/Escritorio/Uni/EGC/uvlhub_hijo/venv/lib/python3.12/site-packages/pymysql/cursors.py", line 153, in execute
    result = self._query(query)
             ^^^^^^^^^^^^^^^^^^
  File "/home/antonio/Escritorio/Uni/EGC/uvlhub_hijo/venv/lib/python3.12/site-packages/pymysql/cursors.py", line 322, in _query
    conn.query(q)
  File "/home/antonio/Escritorio/Uni/EGC/uvlhub_hijo/venv/lib/python3.12/site-packages/pymysql/connections.py", line 563, in query
    self._affected_rows = self._read_query_result(unbuffered=unbuffered)
                          ^^^^^^^^^^^^^^^^^^^^^^^^^^^^^^^^^^^^^^^^^^^^^^
  File "/home/antonio/Escritorio/Uni/EGC/uvlhub_hijo/venv/lib/python3.12/site-packages/pymysql/connections.py", line 825, in _read_query_result
    result.read()
  File "/home/antonio/Escritorio/Uni/EGC/uvlhub_hijo/venv/lib/python3.12/site-packages/pymysql/connections.py", line 1199, in read
    first_packet = self.connection._read_packet()
                   ^^^^^^^^^^^^^^^^^^^^^^^^^^^^^^
  File "/home/antonio/Escritorio/Uni/EGC/uvlhub_hijo/venv/lib/python3.12/site-packages/pymysql/connections.py", line 775, in _read_packet
    packet.raise_for_error()
  File "/home/antonio/Escritorio/Uni/EGC/uvlhub_hijo/venv/lib/python3.12/site-packages/pymysql/protocol.py", line 219, in raise_for_error
    err.raise_mysql_exception(self._data)
  File "/home/antonio/Escritorio/Uni/EGC/uvlhub_hijo/venv/lib/python3.12/site-packages/pymysql/err.py", line 150, in raise_mysql_exception
    raise errorclass(errno, errval)
pymysql.err.ProgrammingError: (1146, "Table 'uvlhubdb.data_set' doesn't exist")

The above exception was the direct cause of the following exception:

Traceback (most recent call last):
  File "/home/antonio/Escritorio/Uni/EGC/uvlhub_hijo/venv/lib/python3.12/site-packages/flask/app.py", line 1473, in wsgi_app
    response = self.full_dispatch_request()
               ^^^^^^^^^^^^^^^^^^^^^^^^^^^^
  File "/home/antonio/Escritorio/Uni/EGC/uvlhub_hijo/venv/lib/python3.12/site-packages/flask/app.py", line 882, in full_dispatch_request
    rv = self.handle_user_exception(e)
         ^^^^^^^^^^^^^^^^^^^^^^^^^^^^^
  File "/home/antonio/Escritorio/Uni/EGC/uvlhub_hijo/venv/lib/python3.12/site-packages/flask_restful/__init__.py", line 298, in error_router
    return original_handler(e)
           ^^^^^^^^^^^^^^^^^^^
  File "/home/antonio/Escritorio/Uni/EGC/uvlhub_hijo/venv/lib/python3.12/site-packages/flask_restful/__init__.py", line 298, in error_router
    return original_handler(e)
           ^^^^^^^^^^^^^^^^^^^
  File "/home/antonio/Escritorio/Uni/EGC/uvlhub_hijo/venv/lib/python3.12/site-packages/flask/app.py", line 880, in full_dispatch_request
    rv = self.dispatch_request()
         ^^^^^^^^^^^^^^^^^^^^^^^
  File "/home/antonio/Escritorio/Uni/EGC/uvlhub_hijo/venv/lib/python3.12/site-packages/flask/app.py", line 865, in dispatch_request
    return self.ensure_sync(self.view_functions[rule.endpoint])(**view_args)  # type: ignore[no-any-return]
           ^^^^^^^^^^^^^^^^^^^^^^^^^^^^^^^^^^^^^^^^^^^^^^^^^^^^^^^^^^^^^^^^^
  File "/home/antonio/Escritorio/Uni/EGC/uvlhub_hijo/app/modules/public/routes.py", line 19, in index
    datasets_counter = dataset_service.count_synchronized_datasets()
                       ^^^^^^^^^^^^^^^^^^^^^^^^^^^^^^^^^^^^^^^^^^^^^
  File "/home/antonio/Escritorio/Uni/EGC/uvlhub_hijo/app/modules/dataset/services.py", line 79, in count_synchronized_datasets
    return self.repository.count_synchronized_datasets()
           ^^^^^^^^^^^^^^^^^^^^^^^^^^^^^^^^^^^^^^^^^^^^^
  File "/home/antonio/Escritorio/Uni/EGC/uvlhub_hijo/app/modules/dataset/repositories.py", line 99, in count_synchronized_datasets
    .count()
     ^^^^^^^
  File "/home/antonio/Escritorio/Uni/EGC/uvlhub_hijo/venv/lib/python3.12/site-packages/sqlalchemy/orm/query.py", line 3112, in count
    self._legacy_from_self(col).enable_eagerloads(False).scalar()
  File "/home/antonio/Escritorio/Uni/EGC/uvlhub_hijo/venv/lib/python3.12/site-packages/sqlalchemy/orm/query.py", line 2805, in scalar
    ret = self.one()
          ^^^^^^^^^^
  File "/home/antonio/Escritorio/Uni/EGC/uvlhub_hijo/venv/lib/python3.12/site-packages/sqlalchemy/orm/query.py", line 2778, in one
    return self._iter().one()  # type: ignore
           ^^^^^^^^^^^^
  File "/home/antonio/Escritorio/Uni/EGC/uvlhub_hijo/venv/lib/python3.12/site-packages/sqlalchemy/orm/query.py", line 2827, in _iter
    result: Union[ScalarResult[_T], Result[_T]] = self.session.execute(
                                                  ^^^^^^^^^^^^^^^^^^^^^
  File "/home/antonio/Escritorio/Uni/EGC/uvlhub_hijo/venv/lib/python3.12/site-packages/sqlalchemy/orm/session.py", line 2351, in execute
    return self._execute_internal(
           ^^^^^^^^^^^^^^^^^^^^^^^
  File "/home/antonio/Escritorio/Uni/EGC/uvlhub_hijo/venv/lib/python3.12/site-packages/sqlalchemy/orm/session.py", line 2236, in _execute_internal
    result: Result[Any] = compile_state_cls.orm_execute_statement(
                          ^^^^^^^^^^^^^^^^^^^^^^^^^^^^^^^^^^^^^^^^
  File "/home/antonio/Escritorio/Uni/EGC/uvlhub_hijo/venv/lib/python3.12/site-packages/sqlalchemy/orm/context.py", line 293, in orm_execute_statement
    result = conn.execute(
             ^^^^^^^^^^^^^
  File "/home/antonio/Escritorio/Uni/EGC/uvlhub_hijo/venv/lib/python3.12/site-packages/sqlalchemy/engine/base.py", line 1418, in execute
    return meth(
           ^^^^^
  File "/home/antonio/Escritorio/Uni/EGC/uvlhub_hijo/venv/lib/python3.12/site-packages/sqlalchemy/sql/elements.py", line 515, in _execute_on_connection
    return connection._execute_clauseelement(
           ^^^^^^^^^^^^^^^^^^^^^^^^^^^^^^^^^^
  File "/home/antonio/Escritorio/Uni/EGC/uvlhub_hijo/venv/lib/python3.12/site-packages/sqlalchemy/engine/base.py", line 1640, in _execute_clauseelement
    ret = self._execute_context(
          ^^^^^^^^^^^^^^^^^^^^^^
  File "/home/antonio/Escritorio/Uni/EGC/uvlhub_hijo/venv/lib/python3.12/site-packages/sqlalchemy/engine/base.py", line 1846, in _execute_context
    return self._exec_single_context(
           ^^^^^^^^^^^^^^^^^^^^^^^^^^
  File "/home/antonio/Escritorio/Uni/EGC/uvlhub_hijo/venv/lib/python3.12/site-packages/sqlalchemy/engine/base.py", line 1986, in _exec_single_context
    self._handle_dbapi_exception(
  File "/home/antonio/Escritorio/Uni/EGC/uvlhub_hijo/venv/lib/python3.12/site-packages/sqlalchemy/engine/base.py", line 2353, in _handle_dbapi_exception
    raise sqlalchemy_exception.with_traceback(exc_info[2]) from e
  File "/home/antonio/Escritorio/Uni/EGC/uvlhub_hijo/venv/lib/python3.12/site-packages/sqlalchemy/engine/base.py", line 1967, in _exec_single_context
    self.dialect.do_execute(
  File "/home/antonio/Escritorio/Uni/EGC/uvlhub_hijo/venv/lib/python3.12/site-packages/sqlalchemy/engine/default.py", line 924, in do_execute
    cursor.execute(statement, parameters)
  File "/home/antonio/Escritorio/Uni/EGC/uvlhub_hijo/venv/lib/python3.12/site-packages/pymysql/cursors.py", line 153, in execute
    result = self._query(query)
             ^^^^^^^^^^^^^^^^^^
  File "/home/antonio/Escritorio/Uni/EGC/uvlhub_hijo/venv/lib/python3.12/site-packages/pymysql/cursors.py", line 322, in _query
    conn.query(q)
  File "/home/antonio/Escritorio/Uni/EGC/uvlhub_hijo/venv/lib/python3.12/site-packages/pymysql/connections.py", line 563, in query
    self._affected_rows = self._read_query_result(unbuffered=unbuffered)
                          ^^^^^^^^^^^^^^^^^^^^^^^^^^^^^^^^^^^^^^^^^^^^^^
  File "/home/antonio/Escritorio/Uni/EGC/uvlhub_hijo/venv/lib/python3.12/site-packages/pymysql/connections.py", line 825, in _read_query_result
    result.read()
  File "/home/antonio/Escritorio/Uni/EGC/uvlhub_hijo/venv/lib/python3.12/site-packages/pymysql/connections.py", line 1199, in read
    first_packet = self.connection._read_packet()
                   ^^^^^^^^^^^^^^^^^^^^^^^^^^^^^^
  File "/home/antonio/Escritorio/Uni/EGC/uvlhub_hijo/venv/lib/python3.12/site-packages/pymysql/connections.py", line 775, in _read_packet
    packet.raise_for_error()
  File "/home/antonio/Escritorio/Uni/EGC/uvlhub_hijo/venv/lib/python3.12/site-packages/pymysql/protocol.py", line 219, in raise_for_error
    err.raise_mysql_exception(self._data)
  File "/home/antonio/Escritorio/Uni/EGC/uvlhub_hijo/venv/lib/python3.12/site-packages/pymysql/err.py", line 150, in raise_mysql_exception
    raise errorclass(errno, errval)
sqlalchemy.exc.ProgrammingError: (pymysql.err.ProgrammingError) (1146, "Table 'uvlhubdb.data_set' doesn't exist")
[SQL: SELECT count(*) AS count_1 
FROM (SELECT data_set.id AS data_set_id, data_set.user_id AS data_set_user_id, data_set.ds_meta_data_id AS data_set_ds_meta_data_id, data_set.created_at AS data_set_created_at 
FROM data_set INNER JOIN ds_meta_data ON ds_meta_data.id = data_set.ds_meta_data_id 
WHERE ds_meta_data.dataset_doi IS NOT NULL) AS anon_1]
(Background on this error at: https://sqlalche.me/e/20/f405)
2024-12-14 19:31:42,628 - app - ERROR - Internal Server Error: 500 Internal Server Error: The server encountered an internal error and was unable to complete your request. Either the server is overloaded or there is an error in the application.
